Workbook

Sheet READ ME
B2: KAYOS: THE NIGHT OF SILENCE — Asset Bible & Generation Tracker
B3: v1.0 · SC Milenwall · July 2026 · Image generation target: Nano Banana 2
B5: HOW TO USE
B6: 1. Work the ASSETS sheet | C6: Filter by Priority and work P1 (Vertical Slice) first. Copy the full prompt from column H straight into Nano Banana 2.
B7: 2. Update Status as you go | C7: Use the dropdown in column I. The DASHBOARD updates itself. Pipeline: Not Started -> Prompted -> Generated -> Cleaned -> Approved -> In Engine.
B8: 3. 'Cleaned' means the pixel pass | C8: Image models produce near-pixel-art, not true pixel art: grids drift and clusters smear. The reliable pipeline is: generate -> downscale to true size -> clean up in Affinity (Pixel studio) — see the AFFINITY PIPELINE sheet -> export PNG. Budget cleanup time for every sprite/tileset.
B9: 4. Keep a style anchor | C9: Generate CH-001 (Elorin) and PO-001 first, get them right, and then ATTACH those images as references in every later character/portrait generation. Reference images are the #1 consistency tool - prompts alone will drift.
B10: 5. One asset, one session | C10: Generate variants of the same asset in the same chat/session with the reference attached, so the model holds the design.
B12: STATUS LEGEND
B13: Not Started | C13: No prompt run yet.
B14: Prompted | C14: Prompt run, output not yet acceptable (iterate).
B15: Generated | C15: An acceptable raw image exists and is saved to the project folder.
B16: Cleaned | C16: Downscaled + pixel-cleaned; true to grid. See AFFINITY PIPELINE sheet.
B17: Approved | C17: Final look signed off against the style anchors.
B18: In Engine | C18: Imported into Godot, filter=Nearest verified, visible in a scene.
B20: PRIORITY LEGEND
B21: P1 - Vertical Slice | C21: Cold Open + Part One Act I (Starfall). Nothing else matters until these are In Engine.
B22: P2 - Part One | C22: Remainder of Elorin's campaign.
B23: P3 - Part Two | C23: Grakkar's campaign.
B24: P4 - Polish | C24: Visions, endings, aftermath, FX, audio.
B26: NANO BANANA 2 TIPS
B27: Backgrounds | C27: Prompts ask for flat magenta backgrounds on sprites - trivial to key out. If the model ignores it, add 'isolated on solid #FF00FF background' verbatim.
B28: Sprite sheets | C28: If a 4-direction sheet comes out scrambled, generate ONE direction per image instead (edit the prompt to 'walk cycle, facing down, 4 frames in a row') - four clean images beat one messy grid.
B29: Tilesets | C29: Treat tileset outputs as REFERENCE ART: rebuild the actual 32px tiles over them (AFFINITY PIPELINE sheet). Models cannot hold a strict tile grid; don't fight it.
B30: Upscaling | C30: Generate large, then downscale to target size with 'nearest neighbour' - never let an art tool smooth-resize pixel art.
B31: Iteration | C31: Keep the winning image of each asset in a /style_anchors folder. That folder becomes the true art bible.
B33: FILE ORGANISATION (suggested)
B34: assets_raw/ | C34: Raw generations, named by asset ID (CH-001_v3.png).
B35: assets_clean/ | C35: Aseprite-cleaned finals, same IDs - these import to Godot.
B36: style_anchors/ | C36: One winning reference image per character/location.
B38: NOTE ON THE EXAMPLE ROW | C38: Row 2 of ASSETS (CH-001) is pre-filled with example Status/Date/Notes values to show the expected format - reset it to 'Not Started' when you begin.

Sheet DASHBOARD
B2: PRODUCTION DASHBOARD
B4: OVERALL
B5: Total assets | C5: =COUNTA(ASSETS!$A$2:$A$500) -> 129
B6: In Engine (done) | C6: =COUNTIF(ASSETS!$I$2:$I$500,"In Engine") -> 0
B7: % complete | C7: =IF(C5=0,0,C6/C5) -> 0
B9: BY STATUS
B10: Not Started | C10: =COUNTIF(ASSETS!$I$2:$I$500,"Not Started") -> 96
B11: Prompted | C11: =COUNTIF(ASSETS!$I$2:$I$500,"Prompted") -> 0
B12: Generated | C12: =COUNTIF(ASSETS!$I$2:$I$500,"Generated") -> 33
B13: Cleaned | C13: =COUNTIF(ASSETS!$I$2:$I$500,"Cleaned") -> 0
B14: Approved | C14: =COUNTIF(ASSETS!$I$2:$I$500,"Approved") -> 0
B15: In Engine | C15: =COUNTIF(ASSETS!$I$2:$I$500,"In Engine") -> 0
B17: BY CATEGORY
B18: Category | C18: Total | D18: In Engine | E18: % done
B19: Character Sprite | C19: =COUNTIF(ASSETS!$B$2:$B$500,"Character Sprite") -> 28 | D19: =COUNTIFS(ASSETS!$B$2:$B$500,"Character Sprite",ASSETS!$I$2:$I$500,"In Engine") -> 0 | E19: =IF(C19=0,0,D19/C19) -> 0
B20: Portrait | C20: =COUNTIF(ASSETS!$B$2:$B$500,"Portrait") -> 14 | D20: =COUNTIFS(ASSETS!$B$2:$B$500,"Portrait",ASSETS!$I$2:$I$500,"In Engine") -> 0 | E20: =IF(C20=0,0,D20/C20) -> 0
B21: Environment | C21: =COUNTIF(ASSETS!$B$2:$B$500,"Environment") -> 16 | D21: =COUNTIFS(ASSETS!$B$2:$B$500,"Environment",ASSETS!$I$2:$I$500,"In Engine") -> 0 | E21: =IF(C21=0,0,D21/C21) -> 0
B22: Prop / Object | C22: =COUNTIF(ASSETS!$B$2:$B$500,"Prop / Object") -> 24 | D22: =COUNTIFS(ASSETS!$B$2:$B$500,"Prop / Object",ASSETS!$I$2:$I$500,"In Engine") -> 0 | E22: =IF(C22=0,0,D22/C22) -> 0
B23: Item Icon | C23: =COUNTIF(ASSETS!$B$2:$B$500,"Item Icon") -> 16 | D23: =COUNTIFS(ASSETS!$B$2:$B$500,"Item Icon",ASSETS!$I$2:$I$500,"In Engine") -> 0 | E23: =IF(C23=0,0,D23/C23) -> 0
B24: UI | C24: =COUNTIF(ASSETS!$B$2:$B$500,"UI") -> 18 | D24: =COUNTIFS(ASSETS!$B$2:$B$500,"UI",ASSETS!$I$2:$I$500,"In Engine") -> 0 | E24: =IF(C24=0,0,D24/C24) -> 0
B25: Story Panel | C25: =COUNTIF(ASSETS!$B$2:$B$500,"Story Panel") -> 10 | D25: =COUNTIFS(ASSETS!$B$2:$B$500,"Story Panel",ASSETS!$I$2:$I$500,"In Engine") -> 0 | E25: =IF(C25=0,0,D25/C25) -> 0
B26: Font / External | C26: =COUNTIF(ASSETS!$B$2:$B$500,"Font / External") -> 3 | D26: =COUNTIFS(ASSETS!$B$2:$B$500,"Font / External",ASSETS!$I$2:$I$500,"In Engine") -> 0 | E26: =IF(C26=0,0,D26/C26) -> 0
B28: BY PRIORITY
B29: Priority | C29: Total | D29: In Engine | E29: % done
B30: P1 - Vertical Slice | C30: =COUNTIF(ASSETS!$E$2:$E$500,"P1 - Vertical Slice") -> 33 | D30: =COUNTIFS(ASSETS!$E$2:$E$500,"P1 - Vertical Slice",ASSETS!$I$2:$I$500,"In Engine") -> 0 | E30: =IF(C30=0,0,D30/C30) -> 0
B31: P2 - Part One | C31: =COUNTIF(ASSETS!$E$2:$E$500,"P2 - Part One") -> 50 | D31: =COUNTIFS(ASSETS!$E$2:$E$500,"P2 - Part One",ASSETS!$I$2:$I$500,"In Engine") -> 0 | E31: =IF(C31=0,0,D31/C31) -> 0
B32: P3 - Part Two | C32: =COUNTIF(ASSETS!$E$2:$E$500,"P3 - Part Two") -> 37 | D32: =COUNTIFS(ASSETS!$E$2:$E$500,"P3 - Part Two",ASSETS!$I$2:$I$500,"In Engine") -> 0 | E32: =IF(C32=0,0,D32/C32) -> 0
B33: P4 - Polish | C33: =COUNTIF(ASSETS!$E$2:$E$500,"P4 - Polish") -> 9 | D33: =COUNTIFS(ASSETS!$E$2:$E$500,"P4 - Polish",ASSETS!$I$2:$I$500,"In Engine") -> 0 | E33: =IF(C33=0,0,D33/C33) -> 0

Sheet AFFINITY PIPELINE
B2: AFFINITY PIPELINE — pixel-art cleanup on the unified Affinity app (macOS)
B3: For: Affinity by Canva (unified app — Pixel / Vector / Layout studios), iMac M4. Shortcuts given Mac-style (Cmd).
B5: THE VERDICT FIRST
B6: Affinity replaces Aseprite for most of this bible | C6: Affinity's Pixel studio is a full raster editor (it is the old Affinity Photo). It can do everything a pixel cleanup pass needs: hard aliased pixels, nearest-neighbour resampling, exact canvases, palettes, PNG export. Use it.
B7: The one real gap: animation | C7: Affinity has NO frame timeline and NO onion skinning. Aseprite's whole reason to exist is animating sprites. For the 28 character sprite sheets (4-direction walk cycles), you can still lay frames out manually on a grid in Affinity — you just can't PREVIEW the animation without exporting and running it in Godot.
B8: My recommendation | C8: Do everything in Affinity. Do NOT buy a second tool yet. Character walk cycles are Phase 6 work — months away. If the no-preview friction actually bites when you get there, add Aseprite (~USD $20) or LibreSprite (free fork) THEN, for sprite sheets only. Don't pre-solve a problem you haven't hit.
B9: Where Affinity is genuinely BETTER than Aseprite | C9: Portraits (PO-001..014), story panels (VS-001..010), all UI (UI-001..018), and the logo. These are painterly or vector work — Aseprite is bad at them, Affinity is excellent. Also: cleaning up raw AI generations (keying out magenta, colour correction, palette unification) is far better in Affinity.
B11: ONE-TIME APP SETUP
B12: 1. Work in the Pixel studio | C12: Switch studios from the selector at the top of the window: Pixel / Vector / Layout. Pixel = the old Affinity Photo = where all sprite/tile cleanup happens. Use Vector studio only for UI panels, icons and the logo.
B13: 2. Turn on Pixel View | C13: Cmd+Opt+Y toggles Pixel View / Vector View. Pixel View shows true rasterised pixels — this is the one you want for all pixel work. (If your art ever looks mysteriously soft, you've flipped to Vector View.)
B14: 3. Set up the grid | C14: Turn on the grid and set spacing to 32 px with 1 division (View menu > grid settings; in the unified app it sits under the View/Guides area). This is your tile grid for every environment and prop sheet.
B15: 4. Turn on snapping | C15: Snapping toggle lives in the toolbar. With Force Pixel Alignment on (Vector studio toolbar), vector shapes land on whole pixels instead of half-pixel mush — essential when building UI that must sit on a 640x360 screen.
B16: 5. Save a KAYOS palette | C16: In the Swatches panel, create a new Document Palette per faction: Noctari (indigo/violet/silver), Solari (gold/ivory/white/dawn-orange), Orc (ash/iron/rust/ember). Build them once from your approved style anchors, then every later asset picks from them. This is how a 129-asset game stays visually coherent.
B18: CANVAS SETUP PER ASSET TYPE
B19: Character sprite frame | C19: 48 x 72 px · 72 DPI · RGB/8 · transparent. Sheet = 4 cols x 4 rows = 192 x 288 px. Feet on the frame's bottom edge. Character height varies by race (see SPRITE SCALE sheet) — Elorin/elves/humans 64 px, orcs 68-70 px, Terran 52 px, children 44 px.
B20: Tileset working canvas | C20: Multiple of 32. Suggested 512 x 512 px (16x16 tiles) · 72 DPI · RGB/8.
B21: Prop / object | C21: Multiples of 32 (32x32, 64x64, 96x64 etc) · transparent background.
B22: Item icon | C22: Exactly 32 x 32 px · transparent.
B23: UI element | C23: Build in VECTOR studio at 2x target size, export at 1x and 2x. 9-slice panels: design the corners at 8-16px so they survive scaling.
B24: Portrait | C24: 512 x 512 px working (painterly, Pixel studio), export a 96 x 96 game version.
B25: Story panel | C25: 1920 x 1080 px · painterly · NOT pixel art (deliberate register shift).
B26: Always | C26: 72 DPI, RGB/8-bit, sRGB. DPI is irrelevant to games but keep it consistent so nothing silently rescales.
B28: TOOLS: USE THESE / AVOID THESE
B29: USE: Pixel Tool | C29: Draws hard, aliased, single pixels. This is THE tool for cleanup. Set width to 1 px.
B30: USE: Flood Fill Tool | C30: Turn anti-aliasing OFF in its options bar before using, or you'll get soft fringe pixels.
B31: USE: Selection tools + Cmd+C/V | C31: Copy-paste is how you build walk-cycle frames: duplicate the idle frame, nudge limbs, repeat.
B32: USE: Colour Picker | C32: Pick from your saved palette constantly. Never introduce a colour that isn't in the faction palette.
B33: AVOID: Paint Brush Tool | C33: It is anti-aliased by design — it will feather your edges and silently destroy pixel art.
B34: AVOID: any Blur / Feather / Soft Shadow / Glow effect | C34: All of them produce in-between pixels. Shade with dithering or discrete colour steps instead.
B35: AVOID: free-transform scaling of pixel layers | C35: Scaling a pixel layer by a non-integer amount resamples it. If you must scale, use whole multiples only.
B36: AVOID: Layer FX / Live Filters on sprites | C36: Fine on portraits and story panels. Fatal on 32px sprites.
B38: THE CLEANUP WORKFLOW (raw generation -> final PNG)
B39: Step 1 — open the raw generation | C39: Open the Nano Banana 2 output in Pixel studio. It will be large (1024px+) and only NEAR pixel art: drifting grid, smeared clusters, anti-aliased edges.
B40: Step 2 — key out the magenta | C40: Select > Select Sampled Colour on the flat magenta background, tolerance low, then delete. (Or Select > Colour Range.) This is why every sprite prompt asks for flat magenta.
B41: Step 3 — downscale with Nearest Neighbour | C41: Document menu > Resize Document. Set target size (e.g. 48 x 72). Set Resampling = NEAREST NEIGHBOUR. Never Bilinear/Bicubic/Lanczos — those blur. NOTE: in the unified app the resize options are still under Document while in Pixel studio, but sit deeper in the menu than they did in v2 — hunt for them once, then remember.
B42: Step 3b — ignore 'Pixel Art' resize | C42: Affinity has a separate 'Pixel Art' resizing option (XBR/HQX, 2x/3x/4x). That's for ENLARGING existing pixel art. It is not what we want here — we're downscaling. Nearest Neighbour is the correct choice.
B43: Step 4 — the actual cleanup (the real work) | C43: At 48x72 the downscale will be a mess. Zoom to 800-1600%, and with the Pixel Tool redraw: fix the silhouette first (it must read instantly at native size), then flatten stray in-between colours onto palette colours, then clean the outline to a single consistent pixel run. Budget 20-45 min per sprite. This is normal and unavoidable.
B44: Step 5 — check at native size | C44: Keep a second view at 100% zoom (Window > New View) while you work at 1600%. If it doesn't read at 100%, it doesn't work — no amount of detail fixes a bad silhouette.
B45: Step 6 — export | C45: File > Export > PNG. Confirm size is exact and resampling is Nearest Neighbour (or 'Don't resample'). Save to assets_clean/ using the asset ID (CH-001.png). Then set Status = Cleaned.
B46: Step 7 — into Godot | C46: Import, then in the Import tab set Filter = OFF / Nearest and re-import. If your sprite looks blurry in-engine, this is always the cause. Then set Status = In Engine.
...

Sheet SPRITE SCALE
A1: Character group | B1: Height in frame | C1: Assets
A2: Children | B2: ~44 px | C2: CH-028
A3: Terran (Durak) | B3: ~52 px (broad) | C3: CH-011
A4: Elves & humans | B4: ~62-64 px | C4: CH-001/002, CH-006-010, CH-012-018, CH-023-027
A5: Void Wardens (armoured) | B5: ~68 px | C5: CH-017
A6: Orcs | B6: ~68-70 px | C6: CH-003/004/005, CH-019-022, CH-028 (adult)
A8: FRAME SPEC (locked 2026-07-17)
A9: Sprite frame | B9: 48 x 72 px | C9: 48 px width confirmed sufficient by the user, 2026-07-17.
A10: Sprite sheet | B10: 192 x 288 px | C10: 4 columns x 4 rows.
A11: Row order | B11: 0=down 1=up 2=right 3=left | C11: Lock this. Confirmed against the cleaned CH-001 sheet 2026-07-17 - the art is the ground truth here, not the other way round.
A12: Baseline | B12: Feet on the frame's bottom edge | C12: Headroom varies; the feet do not.
A13: Tile grid | B13: 32 x 32 px | C13: Tilesets ONLY. Nothing to do with sprite frames.
A15: REFERENCE
A16: CH-001 (Elorin) | B16: 64 px tall in a 48x72 frame | C16: Already produced. Every other elf/human matches her. Do not re-derive this from anything else.
A18: Native viewport is 960 x 540 (GDD S13). | C18: Never judge sprite size in Affinity at 100%. The only honest size check is running the sheet in Godot.

Sheet ASSETS
A1: ID | B1: Category | C1: Asset Name | D1: Used In | E1: Priority | F1: Size / Format | G1: Variants & Animations | H1: Nano Banana 2 Prompt (copy whole cell) | I1: Status | J1: Date Done | K1: Notes
A2: CH-001 | B2: Character Sprite | C2: Elorin Voidweaver (Academy) | D2: P1 all acts | E2: P1 - Vertical Slice | F2: 48x72/frame · 192x288 sheet (4x4) | G2: 3 class palette variants (Voidweaver indigo-black / Harmonist silver-blue / Mender pale green) | H2: HD pixel art character sprite sheet for a top-down 2D dark-fantasy RPG (Zelda: Minish Cap fidelity, 48x72 px per frame). Grid layout: 4 rows = walk down / up / left / right, exactly 4 frames per row (walk cycle: contact-pass-contact-pass), 4 rows only, no extra columns. A Noctari night elf woman, mid-life scholar-archmage: long dark hair, elegant layered academy robes with subtle void-black trim, calm intense bearing. Noctari (night elf) palette: deep indigo, violet, silver starlight accents. Clean readable silhouette, crisp pixel clusters, no anti-aliasing, unified palette, flat solid magenta background for easy removal. | I2: Generated | J2: 2026-07-12 | K2: (EXAMPLE ROW - reset to Not Started) v3 kept; anchor saved to style_anchors/.
A3: CH-002 | B3: Character Sprite | C3: Elorin (exile / travel) | D3: P1 Act III | E3: P2 - Part One | F3: 48x72/frame · 192x288 sheet (4x4) | G3: - | H3: HD pixel art character sprite sheet for a top-down 2D dark-fantasy RPG (Zelda: Minish Cap fidelity, 48x72 px per frame). Grid layout: 4 rows = walk down / up / left / right, exactly 4 frames per row (walk cycle: contact-pass-contact-pass), 4 rows only, no extra columns. Same Noctari woman as CH-001 but in a hooded weathered travel cloak, worn satchel, wearier posture. Noctari (night elf) palette: deep indigo, violet, silver starlight accents. Clean readable silhouette, crisp pixel clusters, no anti-aliasing, unified palette, flat solid magenta background for easy removal. | I3: Not Started | K3: Use CH-001 output as reference image for consistency.
A4: CH-003 | B4: Character Sprite | C4: Grakkar (young, Ashpile) | D4: P2 Act I | E4: P3 - Part Two | F4: 48x72/frame · 192x288 sheet (4x4) | G4: - | H4: HD pixel art character sprite sheet for a top-down 2D dark-fantasy RPG (Zelda: Minish Cap fidelity, 48x72 px per frame). Grid layout: 4 rows = walk down / up / left / right, exactly 4 frames per row (walk cycle: contact-pass-contact-pass), 4 rows only, no extra columns. A young orc labor-slave: lean but broad, ragged work clothes, iron collar, watchful intelligent eyes. orc/Ashpile palette: ash grey, iron, rust, ember orange. Clean readable silhouette, crisp pixel clusters, no anti-aliasing, unified palette, flat solid magenta background for easy removal. | I4: Not Started
A5: CH-004 | B5: Character Sprite | C5: Grakkar (prime, facility) | D5: P2 Act II | E5: P3 - Part Two | F5: 48x72/frame · 192x288 sheet (4x4) | G5: Variant: archive disguise robes | H5: HD pixel art character sprite sheet for a top-down 2D dark-fantasy RPG (Zelda: Minish Cap fidelity, 48x72 px per frame). Grid layout: 4 rows = walk down / up / left / right, exactly 4 frames per row (walk cycle: contact-pass-contact-pass), 4 rows only, no extra columns. The same orc in his prime: massive, scarred, controlled, plain laborer garb concealing discipline. orc/Ashpile palette: ash grey, iron, rust, ember orange. Clean readable silhouette, crisp pixel clusters, no anti-aliasing, unified palette, flat solid magenta background for easy removal. | I5: Not Started | K5: Reference CH-003 output for facial continuity.
A6: CH-005 | B6: Character Sprite | C6: Grakkar the Unbound (the Night) | D6: P2 Act III | E6: P3 - Part Two | F6: 48x72/frame · 192x288 sheet (4x4) | G6: - | H6: HD pixel art character sprite sheet for a top-down 2D dark-fantasy RPG (Zelda: Minish Cap fidelity, 48x72 px per frame). Grid layout: 4 rows = walk down / up / left / right, exactly 4 frames per row (walk cycle: contact-pass-contact-pass), 4 rows only, no extra columns. The same orc as a scarred elder revolutionary: grey-streaked, upright, terrible resolve, dark leathers. orc/Ashpile palette: ash grey, iron, rust, ember orange. Clean readable silhouette, crisp pixel clusters, no anti-aliasing, unified palette, flat solid magenta background for easy removal. | I6: Not Started
A7: CH-006 | B7: Character Sprite | C7: Talindir (apprentice scribe) | D7: Cold Open, P1 | E7: P1 - Vertical Slice | F7: 48x72/frame · 192x288 sheet (4x4) | G7: - | H7: HD pixel art character sprite sheet for a top-down 2D dark-fantasy RPG (Zelda: Minish Cap fidelity, 48x72 px per frame). Grid layout: 4 rows = walk down / up / left / right, exactly 4 frames per row (walk cycle: contact-pass-contact-pass), 4 rows only, no extra columns. A young-looking elf apprentice scribe (~80, youthful for an elf): ink-stained fingers, satchel of scrolls, modest grey-blue robes. Noctari (night elf) palette: deep indigo, violet, silver starlight accents. Clean readable silhouette, crisp pixel clusters, no anti-aliasing, unified palette, flat solid magenta background for easy removal. | I7: Generated
A8: CH-007 | B8: Character Sprite | C8: Talindir (the Night / coda) | D8: Cold Open, Coda | E8: P1 - Vertical Slice | F8: 48x72/frame · 192x288 sheet (4x4) | G8: - | H8: HD pixel art character sprite sheet for a top-down 2D dark-fantasy RPG (Zelda: Minish Cap fidelity, 48x72 px per frame). Grid layout: 4 rows = walk down / up / left / right, exactly 4 frames per row (walk cycle: contact-pass-contact-pass), 4 rows only, no extra columns. The same elf scribe aged and hollowed by catastrophe: dishevelled robes, clutching a chronicle ledger, haunted but resolute. Muted grey-violet palette. Clean readable silhouette, crisp pixel clusters, no anti-aliasing, unified palette, flat solid magenta background for easy removal. | I8: Generated
A9: CH-008 | B9: Character Sprite | C9: Sera (structural enchantress) | D9: P1 | E9: P1 - Vertical Slice | F9: 48x72/frame · 192x288 sheet (4x4) | G9: - | H9: HD pixel art character sprite sheet for a top-down 2D dark-fantasy RPG (Zelda: Minish Cap fidelity, 48x72 px per frame). Grid layout: 4 rows = walk down / up / left / right, exactly 4 frames per row (walk cycle: contact-pass-contact-pass), 4 rows only, no extra columns. A Solari sun elf woman, precise and immaculate: structured gold-white work robes, tool sash of enchanting instruments. Solari (sun elf) palette: radiant gold, ivory, white marble, dawn-orange accents. Clean readable silhouette, crisp pixel clusters, no anti-aliasing, unified palette, flat solid magenta background for easy removal. | I9: Generated
A10: CH-009 | B10: Character Sprite | C10: Coil (Noctari theorist) | D10: P1 | E10: P1 - Vertical Slice | F10: 48x72/frame · 192x288 sheet (4x4) | G10: - | H10: HD pixel art character sprite sheet for a top-down 2D dark-fantasy RPG (Zelda: Minish Cap fidelity, 48x72 px per frame). Grid layout: 4 rows = walk down / up / left / right, exactly 4 frames per row (walk cycle: contact-pass-contact-pass), 4 rows only, no extra columns. A wiry Noctari man, Elorin's former student: rumpled scholar robes, spectacles, armful of notes, nervous energy. Noctari (night elf) palette: deep indigo, violet, silver starlight accents. Clean readable silhouette, crisp pixel clusters, no anti-aliasing, unified palette, flat solid magenta background for easy removal. | I10: Generated
A11: CH-010 | B11: Character Sprite | C11: Vara (human prodigy) | D11: P1 | E11: P1 - Vertical Slice | F11: 48x72/frame · 192x288 sheet (4x4) | G11: - | H11: HD pixel art character sprite sheet for a top-down 2D dark-fantasy RPG (Zelda: Minish Cap fidelity, 48x72 px per frame). Grid layout: 4 rows = walk down / up / left / right, exactly 4 frames per row (walk cycle: contact-pass-contact-pass), 4 rows only, no extra columns. A young human woman prodigy among elves: simple practical clothes, bright alert posture, slightly out of place. Warm earth-tone palette against elven surroundings. Clean readable silhouette, crisp pixel clusters, no anti-aliasing, unified palette, flat solid magenta background for easy removal. | I11: Generated
A12: CH-011 | B12: Character Sprite | C12: Durak Ironthought (Terran geomancer) | D12: P1 | E12: P2 - Part One | F12: 48x72/frame · 192x288 sheet (4x4) | G12: - | H12: HD pixel art character sprite sheet for a top-down 2D dark-fantasy RPG (Zelda: Minish Cap fidelity, 48x72 px per frame). Grid layout: 4 rows = walk down / up / left / right, exactly 4 frames per row (walk cycle: contact-pass-contact-pass), 4 rows only, no extra columns. A stout Terran (dwarf-like earthfolk) geomancer: stone-grey skin, braided beard with copper rings, heavy tool harness, rune-etched chisels. Clean readable silhouette, crisp pixel clusters, no anti-aliasing, unified palette, flat solid magenta background for easy removal. | I12: Not Started
A13: CH-012 | B13: Character Sprite | C13: Seravin Hollow-Water (mentor) | D13: P1 memory scenes | E13: P2 - Part One | F13: 48x72/frame · 192x288 sheet (4x4) | G13: - | H13: HD pixel art character sprite sheet for a top-down 2D dark-fantasy RPG (Zelda: Minish Cap fidelity, 48x72 px per frame). Grid layout: 4 rows = walk down / up / left / right, exactly 4 frames per row (walk cycle: contact-pass-contact-pass), 4 rows only, no extra columns. An elderly Noctari mentor: serene, water-smooth robes in fading blues, walking staff, gentle gravity. Noctari (night elf) palette: deep indigo, violet, silver starlight accents. Clean readable silhouette, crisp pixel clusters, no anti-aliasing, unified palette, flat solid magenta background for easy removal. | I13: Not Started
A14: CH-013 | B14: Character Sprite | C14: Corel (containment archmagister) | D14: P1 | E14: P2 - Part One | F14: 48x72/frame · 192x288 sheet (4x4) | G14: - | H14: HD pixel art character sprite sheet for a top-down 2D dark-fantasy RPG (Zelda: Minish Cap fidelity, 48x72 px per frame). Grid layout: 4 rows = walk down / up / left / right, exactly 4 frames per row (walk cycle: contact-pass-contact-pass), 4 rows only, no extra columns. An exhausted Noctari archmagister: formal high-collared robes gone slightly unkempt, dark-ringed eyes, burden visible in the shoulders. Noctari (night elf) palette: deep indigo, violet, silver starlight accents. Clean readable silhouette, crisp pixel clusters, no anti-aliasing, unified palette, flat solid magenta background for easy removal. | I14: Not Started
A15: CH-014 | B15: Character Sprite | C15: Conclave official (generic) | D15: P1 | E15: P2 - Part One | F15: 48x72/frame · 192x288 sheet (4x4) | G15: 2 color variants | H15: HD pixel art character sprite sheet for a top-down 2D dark-fantasy RPG (Zelda: Minish Cap fidelity, 48x72 px per frame). Grid layout: 4 rows = walk down / up / left / right, exactly 4 frames per row (walk cycle: contact-pass-contact-pass), 4 rows only, no extra columns. A haughty elven Conclave official: ceremonial layered robes, chain of office, imperious bearing. Mixed Noctari/Solari court palette. Clean readable silhouette, crisp pixel clusters, no anti-aliasing, unified palette, flat solid magenta background for easy removal. | I15: Not Started
A16: CH-015 | B16: Character Sprite | C16: Academy student set | D16: P1 | E16: P1 - Vertical Slice | F16: 48x72/frame · 192x288 sheet (4x4) | G16: 3 body/hair variants | H16: HD pixel art character sprite sheet for a top-down 2D dark-fantasy RPG (Zelda: Minish Cap fidelity, 48x72 px per frame). Grid layout: 4 rows = walk down / up / left / right, exactly 4 frames per row (walk cycle: contact-pass-contact-pass), 4 rows only, no extra columns. Young elven academy students in matching study robes with house-color sashes. Noctari (night elf) palette: deep indigo, violet, silver starlight accents. Clean readable silhouette, crisp pixel clusters, no anti-aliasing, unified palette, flat solid magenta background for easy removal. | I16: Generated | K16: Crowd filler for Starfall.
A17: CH-016 | B17: Character Sprite | C17: Academy researcher (generic) | D17: P1 | E17: P2 - Part One | F17: 48x72/frame · 192x288 sheet (4x4) | G17: 2 variants | H17: HD pixel art character sprite sheet for a top-down 2D dark-fantasy RPG (Zelda: Minish Cap fidelity, 48x72 px per frame). Grid layout: 4 rows = walk down / up / left / right, exactly 4 frames per row (walk cycle: contact-pass-contact-pass), 4 rows only, no extra columns. Mid-rank elven researcher: work robes with protective apron, glyph-marked gloves. Noctari (night elf) palette: deep indigo, violet, silver starlight accents. Clean readable silhouette, crisp pixel clusters, no anti-aliasing, unified palette, flat solid magenta background for easy removal. | I17: Not Started
A18: CH-017 | B18: Character Sprite | C18: Void Warden | D18: P1 Act III, P2 Act III | E18: P2 - Part One | F18: 48x72/frame · 192x288 sheet (4x4) | G18: - | H18: HD pixel art character sprite sheet for a top-down 2D dark-fantasy RPG (Zelda: Minish Cap fidelity, 48x72 px per frame). Grid layout: 4 rows = walk down / up / left / right, exactly 4 frames per row (walk cycle: contact-pass-contact-pass), 4 rows only, no extra columns. An elite vault guardian in sealed dark plate armor chased with silver null-glyphs, faceless helm, halberd of black glass. Intimidating silhouette. Clean readable silhouette, crisp pixel clusters, no anti-aliasing, unified palette, flat solid magenta background for easy removal. | I18: Not Started | K18: Appears in BOTH parts - the vault's constant.
A19: CH-018 | B19: Character Sprite | C19: Starfall citizen set | D19: P1 | E19: P2 - Part One | F19: 48x72/frame · 192x288 sheet (4x4) | G19: 4 variants (mixed ages) | H19: HD pixel art character sprite sheet for a top-down 2D dark-fantasy RPG (Zelda: Minish Cap fidelity, 48x72 px per frame). Grid layout: 4 rows = walk down / up / left / right, exactly 4 frames per row (walk cycle: contact-pass-contact-pass), 4 rows only, no extra columns. Ordinary Noctari city folk: merchants, lamplighters, parents, elders. Noctari (night elf) palette: deep indigo, violet, silver starlight accents. Clean readable silhouette, crisp pixel clusters, no anti-aliasing, unified palette, flat solid magenta background for easy removal. | I19: Not Started
A20: CH-019 | B20: Character Sprite | C20: Morga Steelheart | D20: P2 | E20: P3 - Part Two | F20: 48x72/frame · 192x288 sheet (4x4) | G20: - | H20: HD pixel art character sprite sheet for a top-down 2D dark-fantasy RPG (Zelda: Minish Cap fidelity, 48x72 px per frame). Grid layout: 4 rows = walk down / up / left / right, exactly 4 frames per row (walk cycle: contact-pass-contact-pass), 4 rows only, no extra columns. An orc woman elder, the revolution's conscience: iron-grey braids, patched war-coat, carries herself like a judge. orc/Ashpile palette: ash grey, iron, rust, ember orange. Clean readable silhouette, crisp pixel clusters, no anti-aliasing, unified palette, flat solid magenta background for easy removal. | I20: Not Started
A21: CH-020 | B21: Character Sprite | C21: Kess | D21: P2 | E21: P3 - Part Two | F21: 48x72/frame · 192x288 sheet (4x4) | G21: - | H21: HD pixel art character sprite sheet for a top-down 2D dark-fantasy RPG (Zelda: Minish Cap fidelity, 48x72 px per frame). Grid layout: 4 rows = walk down / up / left / right, exactly 4 frames per row (walk cycle: contact-pass-contact-pass), 4 rows only, no extra columns. A young orc courier/agent: quick, slight for an orc, hooded wrap, message tubes at the belt. orc/Ashpile palette: ash grey, iron, rust, ember orange. Clean readable silhouette, crisp pixel clusters, no anti-aliasing, unified palette, flat solid magenta background for easy removal. | I21: Not Started
A22: CH-021 | B22: Character Sprite | C22: Orc laborer set | D22: P2 | E22: P3 - Part Two | F22: 48x72/frame · 192x288 sheet (4x4) | G22: 3 variants | H22: HD pixel art character sprite sheet for a top-down 2D dark-fantasy RPG (Zelda: Minish Cap fidelity, 48x72 px per frame). Grid layout: 4 rows = walk down / up / left / right, exactly 4 frames per row (walk cycle: contact-pass-contact-pass), 4 rows only, no extra columns. Enslaved orc laborers: iron collars, tool harnesses, ash-dusted work clothes, weary strength. orc/Ashpile palette: ash grey, iron, rust, ember orange. Clean readable silhouette, crisp pixel clusters, no anti-aliasing, unified palette, flat solid magenta background for easy removal. | I22: Not Started
A23: CH-022 | B23: Character Sprite | C23: Orc rebel fighter | D23: P2 Act I (Black Crag) | E23: P3 - Part Two | F23: 48x72/frame · 192x288 sheet (4x4) | G23: 2 variants | H23: HD pixel art character sprite sheet for a top-down 2D dark-fantasy RPG (Zelda: Minish Cap fidelity, 48x72 px per frame). Grid layout: 4 rows = walk down / up / left / right, exactly 4 frames per row (walk cycle: contact-pass-contact-pass), 4 rows only, no extra columns. Orc rebellion fighter: improvised armor from labor gear, broken-chain motif painted on chest. orc/Ashpile palette: ash grey, iron, rust, ember orange. Clean readable silhouette, crisp pixel clusters, no anti-aliasing, unified palette, flat solid magenta background for easy removal. | I23: Not Started
A24: CH-023 | B24: Character Sprite | C24: Elven overseer | D24: P2 | E24: P3 - Part Two | F24: 48x72/frame · 192x288 sheet (4x4) | G24: - | H24: HD pixel art character sprite sheet for a top-down 2D dark-fantasy RPG (Zelda: Minish Cap fidelity, 48x72 px per frame). Grid layout: 4 rows = walk down / up / left / right, exactly 4 frames per row (walk cycle: contact-pass-contact-pass), 4 rows only, no extra columns. A cold elven labor overseer: crisp uniform coat, glyph-tipped rod of office, contemptuous posture. Solari (sun elf) palette: radiant gold, ivory, white marble, dawn-orange accents. Clean readable silhouette, crisp pixel clusters, no anti-aliasing, unified palette, flat solid magenta background for easy removal. | I24: Not Started
A25: CH-024 | B25: Character Sprite | C25: Facility researcher (Solari) | D25: P2 | E25: P3 - Part Two | F25: 48x72/frame · 192x288 sheet (4x4) | G25: 2 variants | H25: HD pixel art character sprite sheet for a top-down 2D dark-fantasy RPG (Zelda: Minish Cap fidelity, 48x72 px per frame). Grid layout: 4 rows = walk down / up / left / right, exactly 4 frames per row (walk cycle: contact-pass-contact-pass), 4 rows only, no extra columns. Solari facility researcher: pristine work robes, clipboard scroll-frame, oblivious to the labor around them. Solari (sun elf) palette: radiant gold, ivory, white marble, dawn-orange accents. Clean readable silhouette, crisp pixel clusters, no anti-aliasing, unified palette, flat solid magenta background for easy removal. | I25: Not Started
A26: CH-025 | B26: Character Sprite | C26: Archivist of Astral Wisdom | D26: P2 | E26: P3 - Part Two | F26: 48x72/frame · 192x288 sheet (4x4) | G26: - | H26: HD pixel art character sprite sheet for a top-down 2D dark-fantasy RPG (Zelda: Minish Cap fidelity, 48x72 px per frame). Grid layout: 4 rows = walk down / up / left / right, exactly 4 frames per row (walk cycle: contact-pass-contact-pass), 4 rows only, no extra columns. An ancient elven archivist: dust-colored robes, key-ring of dozens of archive keys, lantern-staff. Solari (sun elf) palette: radiant gold, ivory, white marble, dawn-orange accents. Clean readable silhouette, crisp pixel clusters, no anti-aliasing, unified palette, flat solid magenta background for easy removal. | I26: Not Started
A27: CH-026 | B27: Character Sprite | C27: Solari Tower guard | D27: P1 Act III, P2 Act III | E27: P2 - Part One | F27: 48x72/frame · 192x288 sheet (4x4) | G27: 2 variants | H27: HD pixel art character sprite sheet for a top-down 2D dark-fantasy RPG (Zelda: Minish Cap fidelity, 48x72 px per frame). Grid layout: 4 rows = walk down / up / left / right, exactly 4 frames per row (walk cycle: contact-pass-contact-pass), 4 rows only, no extra columns. Tower of Celestial Harmony guard: gilded ceremonial half-plate, sun-disc shield, spear. Solari (sun elf) palette: radiant gold, ivory, white marble, dawn-orange accents. Clean readable silhouette, crisp pixel clusters, no anti-aliasing, unified palette, flat solid magenta background for easy removal. | I27: Not Started | K27: Shared across both parts - build once.
A28: CH-027 | B28: Character Sprite | C28: Astra'Thalas citizen set | D28: P1 Act III, P2 Act III | E28: P2 - Part One | F28: 48x72/frame · 192x288 sheet (4x4) | G28: 3 variants | H28: HD pixel art character sprite sheet for a top-down 2D dark-fantasy RPG (Zelda: Minish Cap fidelity, 48x72 px per frame). Grid layout: 4 rows = walk down / up / left / right, exactly 4 frames per row (walk cycle: contact-pass-contact-pass), 4 rows only, no extra columns. Solari capital citizens in festival dress for the solstice. Solari (sun elf) palette: radiant gold, ivory, white marble, dawn-orange accents. Clean readable silhouette, crisp pixel clusters, no anti-aliasing, unified palette, flat solid magenta background for easy removal. | I28: Not Started
A29: CH-028 | B29: Character Sprite | C29: Ashpile child | D29: P2 Act I | E29: P3 - Part Two | F29: 48x72/frame · 192x288 sheet (4x4) | G29: 2 variants | H29: HD pixel art character sprite sheet for a top-down 2D dark-fantasy RPG (Zelda: Minish Cap fidelity, 48x72 px per frame). Grid layout: 4 rows = walk down / up / left / right, exactly 4 frames per row (walk cycle: contact-pass-contact-pass), 4 rows only, no extra columns. Orc children of the birth-camp: small, quick, ragged, resilient. orc/Ashpile palette: ash grey, iron, rust, ember orange. Clean readable silhouette, crisp pixel clusters, no anti-aliasing, unified palette, flat solid magenta background for easy removal. | I29: Not Started
A30: PO-001 | B30: Portrait | C30: Elorin — composed | D30: P1 | E30: P1 - Vertical Slice | F30: 512x512 source -> 96x96 in-game | G30: Expressions: neutral / strained / grieved | H30: Painted character portrait for RPG dialogue UI: bust framing, three-quarter view, dark-fantasy oil-painting style in the tradition of classic CRPG portraits, dramatic single-source lighting, plain very dark background, square composition. A Noctari night elf woman archmage in mid-life: sharp intelligent features, long dark hair, layered indigo academy robes with void-black trim, quiet authority and buried doubt in the eyes. Noctari (night elf) palette: deep indigo, violet, silver starlight accents. | I30: Generated | K30: Keep one style seed/reference across ALL portraits.
A31: PO-002 | B31: Portrait | C31: Grakkar — young | D31: P2 | E31: P3 - Part Two | F31: 512x512 source -> 96x96 in-game | G31: Expressions: guarded / defiant | H31: Painted character portrait for RPG dialogue UI: bust framing, three-quarter view, dark-fantasy oil-painting style in the tradition of classic CRPG portraits, dramatic single-source lighting, plain very dark background, square composition. A young orc slave with watchful, fiercely intelligent eyes, iron collar, ash-dusted skin, unbroken pride. orc/Ashpile palette: ash grey, iron, rust, ember orange. | I31: Not Started | K31: Keep one style seed/reference across ALL portraits.
A32: PO-003 | B32: Portrait | C32: Grakkar — the Unbound | D32: P2 | E32: P3 - Part Two | F32: 512x512 source -> 96x96 in-game | G32: Expressions: resolute / grieving / terrible | H32: Painted character portrait for RPG dialogue UI: bust framing, three-quarter view, dark-fantasy oil-painting style in the tradition of classic CRPG portraits, dramatic single-source lighting, plain very dark background, square composition. An elder orc revolutionary: grey-streaked hair, old scars, eyes that have carried a plan for two centuries. Ash and ember palette. | I32: Not Started | K32: Keep one style seed/reference across ALL portraits.
A33: PO-004 | B33: Portrait | C33: Talindir — apprentice | D33: Cold Open, P1 | E33: P1 - Vertical Slice | F33: 512x512 source -> 96x96 in-game | G33: Expressions: eager / uneasy | H33: Painted character portrait for RPG dialogue UI: bust framing, three-quarter view, dark-fantasy oil-painting style in the tradition of classic CRPG portraits, dramatic single-source lighting, plain very dark background, square composition. A youthful elf scribe with ink-stained fingers and earnest eyes, grey-blue modest robes. | I33: Generated | K33: Keep one style seed/reference across ALL portraits.
A34: PO-005 | B34: Portrait | C34: Talindir — chronicler | D34: Cold Open, Coda | E34: P1 - Vertical Slice | F34: 512x512 source -> 96x96 in-game | G34: Expressions: hollowed / resolved | H34: Painted character portrait for RPG dialogue UI: bust framing, three-quarter view, dark-fantasy oil-painting style in the tradition of classic CRPG portraits, dramatic single-source lighting, plain very dark background, square composition. The same elf scribe aged by catastrophe: gaunt, haunted, holding a ledger like a wound. | I34: Generated | K34: Keep one style seed/reference across ALL portraits.
A35: PO-006 | B35: Portrait | C35: Sera | D35: P1 | E35: P1 - Vertical Slice | F35: 512x512 source -> 96x96 in-game | G35: Expressions: precise / warm (rare) | H35: Painted character portrait for RPG dialogue UI: bust framing, three-quarter view, dark-fantasy oil-painting style in the tradition of classic CRPG portraits, dramatic single-source lighting, plain very dark background, square composition. A Solari sun elf enchantress: immaculate, geometric gold jewelry, appraising gaze. Solari (sun elf) palette: radiant gold, ivory, white marble, dawn-orange accents. | I35: Generated | K35: Keep one style seed/reference across ALL portraits.
A36: PO-007 | B36: Portrait | C36: Coil | D36: P1 | E36: P1 - Vertical Slice | F36: 512x512 source -> 96x96 in-game | G36: Expressions: animated / anxious | H36: Painted character portrait for RPG dialogue UI: bust framing, three-quarter view, dark-fantasy oil-painting style in the tradition of classic CRPG portraits, dramatic single-source lighting, plain very dark background, square composition. A wiry Noctari theorist with spectacles, ink smudges, and the face of a man who sees the mathematics before the consequences. | I36: Generated | K36: Keep one style seed/reference across ALL portraits.
A37: PO-008 | B37: Portrait | C37: Vara | D37: P1 | E37: P1 - Vertical Slice | F37: 512x512 source -> 96x96 in-game | G37: Expressions: bright / wounded | H37: Painted character portrait for RPG dialogue UI: bust framing, three-quarter view, dark-fantasy oil-painting style in the tradition of classic CRPG portraits, dramatic single-source lighting, plain very dark background, square composition. A young human woman among elves: open face, quick eyes, plain clothes, quietly aware she must be twice as good. | I37: Generated | K37: Keep one style seed/reference across ALL portraits.
A38: PO-009 | B38: Portrait | C38: Durak Ironthought | D38: P1 | E38: P2 - Part One | F38: 512x512 source -> 96x96 in-game | G38: Expressions: dry / grave | H38: Painted character portrait for RPG dialogue UI: bust framing, three-quarter view, dark-fantasy oil-painting style in the tradition of classic CRPG portraits, dramatic single-source lighting, plain very dark background, square composition. A stout Terran geomancer: stone-grey skin, copper-ringed beard, patient mountain-deep eyes. | I38: Not Started | K38: Keep one style seed/reference across ALL portraits.
A39: PO-010 | B39: Portrait | C39: Seravin Hollow-Water | D39: P1 memories | E39: P2 - Part One | F39: 512x512 source -> 96x96 in-game | G39: Expressions: serene | H39: Painted character portrait for RPG dialogue UI: bust framing, three-quarter view, dark-fantasy oil-painting style in the tradition of classic CRPG portraits, dramatic single-source lighting, plain very dark background, square composition. An elderly Noctari mentor, serene as still water, fading blue robes, kindness with edges. | I39: Not Started | K39: Keep one style seed/reference across ALL portraits.
A40: PO-011 | B40: Portrait | C40: Corel | D40: P1 | E40: P2 - Part One | F40: 512x512 source -> 96x96 in-game | G40: Expressions: exhausted / alarmed | H40: Painted character portrait for RPG dialogue UI: bust framing, three-quarter view, dark-fantasy oil-painting style in the tradition of classic CRPG portraits, dramatic single-source lighting, plain very dark background, square composition. An exhausted Noctari archmagister: dark-ringed eyes, formal collar askew, decency worn thin by duty. | I40: Not Started | K40: Keep one style seed/reference across ALL portraits.
...
